Workbook

Sheet Data_input
A1: CAMPUS_ID | B1: Student_ID | C1: Name | D1: Program_Status | E1: Program | F1: Admint_Term | G1: Admission_Date | H1: AdmitTermBeginDate | I1: ExpectedGradTerm | J1: Campus | K1: Study_Method | L1: Prog_short_Des | M1: Program_Description | N1: Faculty_Description | O1: RPD_RegisterDate | P1: ThesisSem_ActualDate | Q1: RPD_ActualDate | R1: PublicationRequirement_paper1_ActualDay（PHD/Master） | S1: PublicationRequirement_paper2_ActualDay（PHD）
A2: 247R1 | B2: 250PA247R8 | C2: USMAN YAU | D2: Active in Program | E2: MATR | F2: 2500 | G2: 45678 | H2: 45658 | I2: 3000 | J2: CYBER | K2: Full-Time | L2: Ph.D. (Eng) | M2: Doctor of Philosophy (Engineering) | N2: Faculty of AI and Engineering | O2: 45679 | P2: 47239 | Q2: 45841 | R2: 45682 | S2: 46245
A3: 247R4 | B3: 250PA247R1 | C3: KHAN IRFAN | D3: Active in Program | E3: MATR | F3: 2500 | G3: 45709 | H3: 45658 | I3: 3000 | J3: CYBER | K3: Full-Time | L3: Ph.D. (Eng) | M3: Doctor of Philosophy (Engineering) | N3: Faculty of AI and Engineering | O3: 45680 | P3: 47228 | Q3: 45872 | R3: 46237 | S3: 46246
A4: 247R8 | B4: 250PA247R2 | C4: JAYAKANTHAN A/L M. LACHMANAN | D4: Active in Program | E4: MATR | F4: 2500 | G4: 45696 | H4: 45658 | I4: 3000 | J4: CYBER | K4: Full-Time | L4: Ph.D. (Eng) | M4: Doctor of Philosophy (Engineering) | N4: Faculty of AI and Engineering | O4: 45697 | P4: 47262 | Q4: 45873 | R4: 46206 | S4: 46215
A5: 247R3 | B5: 250PA247R5 | C5: IDRIS OLALEKAN ADEOYE | D5: Active in Program | E5: MATR | F5: 2500 | G5: 45662 | H5: 45658 | I5: 3000 | J5: CYBER | K5: Full-Time | L5: Ph.D. (Eng) | M5: Doctor of Philosophy (Engineering) | N5: Faculty of AI and Engineering | O5: 45663 | P5: 47340 | Q5: 45875 | R5: 46239 | S5: 46248
A6: 247R7 | B6: 250PA247R7 | C6: NUHU DAN-AZUMI MUHAMMAD | D6: Active in Program | E6: MATR | F6: 2500 | G6: 45662 | H6: 45658 | I6: 3000 | J6: CYBER | K6: Full-Time | L6: Ph.D. (Eng) | M6: Doctor of Philosophy (Engineering) | N6: Faculty of AI and Engineering | O6: 45663 | P6: 47346 | Q6: 45875 | R6: 46240 | S6: 46249
A7: 2508F | B7: 250PA257R3 | C7: NAZ ANUM | D7: Active in Program | E7: MATR | F7: 2500 | G7: 45661 | H7: 45658 | I7: 3000 | J7: CYBER | K7: Full-Time | L7: Ph.D. (Eng) | M7: Doctor of Philosophy (Engineering) | N7: Faculty of AI and Engineering | O7: 45662 | P7: 47342 | Q7: 45876 | R7: 46241 | S7: 46250
A8: 243YN | B8: 250PA237R1 | C8: NUR SYAZA BINTI ZAKARIA | D8: Active in Program | E8: MATR | F8: 2500 | G8: 45695 | H8: 45658 | I8: 3000 | J8: CYBER | K8: Full-Time | L8: Ph.D. (Eng) | M8: Doctor of Philosophy (Engineering) | N8: Faculty of AI and Engineering | O8: 45696 | P8: 47496 | Q8: 46242 | R8: 46607 | S8: 46607
A9: 251D4 | B9: 250PK242QD | C9: YANG XIAO | D9: Active in Program | E9: MATR | F9: 2500 | G9: 45738 | H9: 45658 | I9: 3000 | J9: CYBER | K9: Full-Time | L9: Ph.D. (Communication) | M9: Doctor of Philosophy (Communication) | N9: Faculty of Applied Comm | O9: 45739 | P9: 47497 | Q9: 46121 | R9: 46608 | S9: 46610
A10: 2458H | B10: 250PK232QD | C10: MD MUSLIM UDDIN AHMED PIPUL | D10: Active in Program | E10: MATR | F10: 2500 | G10: 45724 | H10: 45658 | I10: 3000 | J10: CYBER | K10: Full-Time | L10: Ph.D. (Communication) | M10: Doctor of Philosophy (Communication) | N10: Faculty of Applied Comm | O10: 45725 | P10: 47498 | Q10: 46244 | R10: 46609 | S10: 46609
A11: 252QD | B11: 250PK222QD | C11: JOANNA A/P JAYAPRAKASH | D11: Active in Program | E11: MATR | F11: 2500 | G11: 45704 | H11: 45658 | I11: 3000 | J11: CYBER | K11: Full-Time | L11: Ph.D. (Communication) | M11: Doctor of Philosophy (Communication) | N11: Faculty of Applied Comm | O11: 45705 | P11: 47499 | Q11: 46245 | R11: 46610 | S11: 46610
A12: 243YN | B12: 250PK212QD | C12: HAMZA BASHER ALAMIN BARKA | D12: Active in Program | E12: MATR | F12: 2500 | G12: 45662 | H12: 45658 | I12: 3000 | J12: CYBER | K12: Part-Time | L12: Ph.D. (Communication) | M12: Doctor of Philosophy (Communication) | N12: Faculty of Applied Comm | O12: 45663 | P12: 47225 | Q12: 45795 | R12: 45759 | S12: 45759
A13: 247R7 | B13: 250PK272QD | C13: NAHIDA FERDOUS | D13: Active in Program | E13: MATR | F13: 2500 | G13: 45695 | H13: 45658 | I13: 3000 | J13: CYBER | K13: Part-Time | L13: Ph.D. (Communication) | M13: Doctor of Philosophy (Communication) | N13: Faculty of Applied Comm | O13: 45696 | P13: 47226 | Q13: 45765 | R13: 46125 | S13: 46135
... A20: 247R9 | B20: 250PA213RK | C20: AHMAD FAISAL BIN YUSOF | D20: Active in Program | E20: MATR | F20: 2500 | G20: 45662 | H20: 45658 | I20: 3000 | J20: MLAKA | K20: Part-Time | L20: Ph.D. (Mgmt.) | M20: Doctor of Philosophy (Management) | N20: Faculty of Business | O20: 45663 | P20: 48238 | Q20: 46136 | R20: 46619 | S20: 46619
A21: 243A9 | B21: 250PK245T1 | C21: HANG JIA YEE | D21: Active in Program | E21: MATR | F21: 2500 | G21: 45663 | H21: 45658 | I21: 3000 | J21: MLAKA | K21: Full-Time | L21: Master (Mgmt) | M21: Master of Philosophy (Management) | N21: Faculty of Business | O21: 45664 | P21: 46508 | Q21: 45768 | R21: 45828
A22: 248RK | B22: 250PH272RM | C22: LEE KOK MING | D22: Active in Program | E22: MATR | F22: 2500 | G22: 45685 | H22: 45658 | I22: 3000 | J22: MLAKA | K22: Full-Time | L22: Master (Mgmt) | M22: Master of Philosophy (Management) | N22: Faculty of Business | O22: 45686 | P22: 46532 | Q22: 45798 | R22: 45798
A23: 249YH | B23: 250PN281Q2 | C23: SITI NUR AIN BINTI RAHMAN | D23: Active in Program | E23: MATR | F23: 2500 | G23: 45686 | H23: 45658 | I23: 3000 | J23: MLAKA | K23: Full-Time | L23: Master (Mgmt) | M23: Master of Philosophy (Management) | N23: Faculty of Business | O23: 45687 | P23: 46539 | Q23: 45798 | R23: 45830
A24: 2468Z | B24: 250PM269QD | C24: RAHUL KUMAR SINGH | D24: Active in Program | E24: MATR | F24: 2500 | G24: 45710 | H24: 45658 | I24: 3000 | J24: MLAKA | K24: Full-Time | L24: Master (Mgmt) | M24: Master of Philosophy (Management) | N24: Faculty of Business | O24: 45711 | P24: 46631 | Q24: 45921 | R24: 45922
A25: 247JK | B25: 250PJ258RD | C25: CHAN WEI HONG | D25: Active in Program | E25: MATR | F25: 2500 | G25: 45711 | H25: 45658 | I25: 3000 | J25: MLAKA | K25: Full-Time | L25: Master (Law) | M25: Master of Laws | N25: Faculty of Law | O25: 45712 | P25: 46661 | Q25: 45890 | R25: 45931
A26: 245PL | B26: 250PL293T1 | C26: NURUL HUDA BINTI AZIZ | D26: Active in Program | E26: MATR | F26: 2500 | G26: 45689 | H26: 45658 | I26: 3000 | J26: MLAKA | K26: Full-Time | L26: Master (Law) | M26: Master of Laws | N26: Faculty of Law | O26: 45690 | P26: 46692 | Q26: 45927 | R26: 45952
A27: 244XM | B27: 250PR241PD | C27: MOHAMMAD ALI KHAN | D27: Active in Program | E27: MATR | F27: 2500 | G27: 45690 | H27: 45658 | I27: 3000 | J27: MLAKA | K27: Full-Time | L27: Master (Law) | M27: Master of Laws | N27: Faculty of Law | O27: 45691 | P27: 46755 | Q27: 46059 | R27: 46154
A28: 2495N | B28: 250PB237QK | C28: TAN JIA WEI | D28: Active in Program | E28: MATR | F28: 2500 | G28: 45691 | H28: 45658 | I28: 3000 | J28: MLAKA | K28: Full-Time | L28: Master (Law) | M28: Master of Laws | N28: Faculty of Law | O28: 45692 | P28: 46760 | Q28: 46060 | R28: 46155
A29: 246ZP | B29: 250PC276R2 | C29: FARHAN BIN ISMAIL | D29: Active in Program | E29: MATR | F29: 2500 | G29: 45671 | H29: 45658 | I29: 3000 | J29: MLAKA | K29: Full-Time | L29: Master (Law) | M29: Master of Laws | N29: Faculty of Law | O29: 45672 | P29: 46764 | Q29: 46061 | R29: 46135
A30: 247QR | B30: 250PE261RJ | C30: LIM PEI YEE | D30: Active in Program | E30: MATR | F30: 2500 | G30: 45672 | H30: 45658 | I30: 3000 | J30: MLAKA | K30: Full-Time | L30: Master (Mgmt) | M30: Master of Philosophy (Management) | N30: Faculty of Business | O30: 45673 | P30: 46770 | Q30: 46059 | R30: 46157
A31: 248R7 | B31: 250PG248PD | C31: RAJESH PRASAD | D31: Active in Program | E31: MATR | F31: 2500 | G31: 45673 | H31: 45658 | I31: 3000 | J31: MLAKA | K31: Part-Time | L31: Master (Mgmt) | M31: Master of Philosophy (Management) | N31: Faculty of Business | O31: 45674 | P31: 47256 | Q31: 45753 | R31: 45828
A32: 2458T | B32: 250PH234RM | C32: GOH MUN KIT | D32: Active in Program | E32: MATR | F32: 2500 | G32: 45661 | H32: 45658 | I32: 3000 | J32: MLAKA | K32: Part-Time | L32: Master (Mgmt) | M32: Master of Philosophy (Management) | N32: Faculty of Business | O32: 45662 | P32: 47287 | Q32: 45768 | R32: 45798
... A40: 247LH | B40: 250PS297RL | C40: KOH CHEE MING | D40: Active in Program | E40: MATR | F40: 2500 | G40: 45682 | H40: 45658 | I40: 3000 | J40: CYBER | K40: Part-Time | L40: Master (Communication) | M40: Master of Philosophy in Communication | N40: Faculty of Applied Comm | O40: 45683 | P40: 47504 | Q40: 46056 | R40: 46157
A41: 247LH | B41: 250PS297RL | C41: ANG ANSON | D41: Active in Program | E41: MATR | F41: 2500 | G41: 45682 | H41: 45658 | I41: 3000 | J41: CYBER | K41: Full-Time | L41: Master (Communication) | M41: Master of Philosophy in Communication | N41: Faculty of Applied Comm | O41: 45682

Sheet data_coll
A1: CAMPUS_ID | B1: Student_ID | C1: Name | D1: Program_Status | E1: Program | F1: Admint_Term | G1: Admission_Date | H1: AdmitTermBeginDate | I1: ExpectedEnd_StudyDate | J1: ExpectedGradTerm | K1: Campus | L1: Study_Method | M1: Prog_short_Des | N1: Program_Description | O1: Faculty_Description | P1: RPD_RegisterDate | Q1: RPD_MAXDate | R1: RPD_ActualDate | S1: ThesisSem_StartDate | T1: ThesisSem_ActualDate | U1: ThesisSem_MAXDate | V1: PublicationRequirement_MAXDate | W1: PublicationRequirement_Actual_paper1 | X1: PublicationRequirement_Actual_paper2
A2: =IF(Data_input!A2="","",Data_input!A2) -> 247R1 | B2: =IF(Data_input!B2="","",Data_input!B2) -> 250PA247R8 | C2: =IF(Data_input!C2="","",Data_input!C2) -> USMAN YAU | D2: =IF(Data_input!D2="","",Data_input!D2) -> Active in Program | E2: =IF(Data_input!E2="","",Data_input!E2) -> MATR | F2: =IF(Data_input!F2="","",Data_input!F2) -> 2500 | G2: =IF(Data_input!G2="","",Data_input!G2) -> 45678 | H2: =IF(Data_input!H2="","",Data_input!H2) -> 45658 | I2: =IF(OR(H2="",L2=""),"", IF(ISNUMBER(SEARCH("Ph.D",M2)), IF(L2="Full-Time",EDATE(H2,12*5),EDATE(H2,12*7)), IF(L2="Full-Time",EDATE(H2,12*3),EDATE(H2,12*5)) )) -> 47484 | J2: =IF(Data_input!I2="","",Data_input!I2) -> 3000 | K2: =IF(Data_input!J2="","",Data_input!J2) -> CYBER | L2: =IF(Data_input!K2="","",Data_input!K2) -> Full-Time | M2: =IF(Data_input!L2="","",Data_input!L2) -> Ph.D. (Eng) | N2: =IF(Data_input!M2="","",Data_input!M2) -> Doctor of Philosophy (Engineering) | O2: =IF(Data_input!N2="","",Data_input!N2) -> Faculty of AI and Engineering | P2: =IF(Data_input!O2="","",Data_input!O2) -> 45679 | Q2: =IF(P2="","",EDATE(P2,12)) -> 46044 | R2: =IF(Data_input!Q2="","",Data_input!Q2) -> 45841 | S2: =IF(I2="","",DATE(YEAR(I2)-1,MONTH(I2),DAY(I2))) -> 47119 | T2: =IF(LEN(TRIM(Data_input!P2))=0,"",Data_input!P2) -> 47239 | U2: =IF(I2="","",I2) -> 47484 | V2: =IF(G2="","", IF(ISNUMBER(SEARCH("Ph.D",M2)), EDATE(G2,24), EDATE(G2,15))) -> 46408 | W2: =IF(Data_input!R2="","",Data_input!R2) -> 45682 | X2: =IF(Data_input!S2="","",Data_input!S2) -> 46245
A3: =IF(Data_input!A3="","",Data_input!A3) -> 247R4 | B3: =IF(Data_input!B3="","",Data_input!B3) -> 250PA247R1 | C3: =IF(Data_input!C3="","",Data_input!C3) -> KHAN IRFAN | D3: =IF(Data_input!D3="","",Data_input!D3) -> Active in Program | E3: =IF(Data_input!E3="","",Data_input!E3) -> MATR | F3: =IF(Data_input!F3="","",Data_input!F3) -> 2500 | G3: =IF(Data_input!G3="","",Data_input!G3) -> 45709 | H3: =IF(Data_input!H3="","",Data_input!H3) -> 45658 | I3: =IF(OR(H3="",L3=""),"", IF(ISNUMBER(SEARCH("Ph.D",M3)), IF(L3="Full-Time",EDATE(H3,12*5),EDATE(H3,12*7)), IF(L3="Full-Time",EDATE(H3,12*3),EDATE(H3,12*5)) )) -> 47484 | J3: =IF(Data_input!I3="","",Data_input!I3) -> 3000 | K3: =IF(Data_input!J3="","",Data_input!J3) -> CYBER | L3: =IF(Data_input!K3="","",Data_input!K3) -> Full-Time | M3: =IF(Data_input!L3="","",Data_input!L3) -> Ph.D. (Eng) | N3: =IF(Data_input!M3="","",Data_input!M3) -> Doctor of Philosophy (Engineering) | O3: =IF(Data_input!N3="","",Data_input!N3) -> Faculty of AI and Engineering | P3: =IF(Data_input!O3="","",Data_input!O3) -> 45680 | Q3: =IF(P3="","",EDATE(P3,12)) -> 46045 | R3: =IF(Data_input!Q3="","",Data_input!Q3) -> 45872 | S3: =IF(I3="","",DATE(YEAR(I3)-1,MONTH(I3),DAY(I3))) -> 47119 | T3: =IF(LEN(TRIM(Data_input!P3))=0,"",Data_input!P3) -> 47228 | U3: =IF(I3="","",I3) -> 47484 | V3: =IF(G3="","", IF(ISNUMBER(SEARCH("Ph.D",M3)), EDATE(G3,24), EDATE(G3,15))) -> 46439 | W3: =IF(Data_input!R3="","",Data_input!R3) -> 46237 | X3: =IF(Data_input!S3="","",Data_input!S3) -> 46246
A4: =IF(Data_input!A4="","",Data_input!A4) -> 247R8 | B4: =IF(Data_input!B4="","",Data_input!B4) -> 250PA247R2 | C4: =IF(Data_input!C4="","",Data_input!C4) -> JAYAKANTHAN A/L M. LACHMANAN | D4: =IF(Data_input!D4="","",Data_input!D4) -> Active in Program | E4: =IF(Data_input!E4="","",Data_input!E4) -> MATR | F4: =IF(Data_input!F4="","",Data_input!F4) -> 2500 | G4: =IF(Data_input!G4="","",Data_input!G4) -> 45696 | H4: =IF(Data_input!H4="","",Data_input!H4) -> 45658 | I4: =IF(OR(H4="",L4=""),"", IF(ISNUMBER(SEARCH("Ph.D",M4)), IF(L4="Full-Time",EDATE(H4,12*5),EDATE(H4,12*7)), IF(L4="Full-Time",EDATE(H4,12*3),EDATE(H4,12*5)) )) -> 47484 | J4: =IF(Data_input!I4="","",Data_input!I4) -> 3000 | K4: =IF(Data_input!J4="","",Data_input!J4) -> CYBER | L4: =IF(Data_input!K4="","",Data_input!K4) -> Full-Time | M4: =IF(Data_input!L4="","",Data_input!L4) -> Ph.D. (Eng) | N4: =IF(Data_input!M4="","",Data_input!M4) -> Doctor of Philosophy (Engineering) | O4: =IF(Data_input!N4="","",Data_input!N4) -> Faculty of AI and Engineering | P4: =IF(Data_input!O4="","",Data_input!O4) -> 45697 | Q4: =IF(P4="","",EDATE(P4,12)) -> 46062 | R4: =IF(Data_input!Q4="","",Data_input!Q4) -> 45873 | S4: =IF(I4="","",DATE(YEAR(I4)-1,MONTH(I4),DAY(I4))) -> 47119 | T4: =IF(LEN(TRIM(Data_input!P4))=0,"",Data_input!P4) -> 47262 | U4: =IF(I4="","",I4) -> 47484 | V4: =IF(G4="","", IF(ISNUMBER(SEARCH("Ph.D",M4)), EDATE(G4,24), EDATE(G4,15))) -> 46426 | W4: =IF(Data_input!R4="","",Data_input!R4) -> 46206 | X4: =IF(Data_input!S4="","",Data_input!S4) -> 46215
A5: =IF(Data_input!A5="","",Data_input!A5) -> 247R3 | B5: =IF(Data_input!B5="","",Data_input!B5) -> 250PA247R5 | C5: =IF(Data_input!C5="","",Data_input!C5) -> IDRIS OLALEKAN ADEOYE | D5: =IF(Data_input!D5="","",Data_input!D5) -> Active in Program | E5: =IF(Data_input!E5="","",Data_input!E5) -> MATR | F5: =IF(Data_input!F5="","",Data_input!F5) -> 2500 | G5: =IF(Data_input!G5="","",Data_input!G5) -> 45662 | H5: =IF(Data_input!H5="","",Data_input!H5) -> 45658 | I5: =IF(OR(H5="",L5=""),"", IF(ISNUMBER(SEARCH("Ph.D",M5)), IF(L5="Full-Time",EDATE(H5,12*5),EDATE(H5,12*7)), IF(L5="Full-Time",EDATE(H5,12*3),EDATE(H5,12*5)) )) -> 47484 | J5: =IF(Data_input!I5="","",Data_input!I5) -> 3000 | K5: =IF(Data_input!J5="","",Data_input!J5) -> CYBER | L5: =IF(Data_input!K5="","",Data_input!K5) -> Full-Time | M5: =IF(Data_input!L5="","",Data_input!L5) -> Ph.D. (Eng) | N5: =IF(Data_input!M5="","",Data_input!M5) -> Doctor of Philosophy (Engineering) | O5: =IF(Data_input!N5="","",Data_input!N5) -> Faculty of AI and Engineering | P5: =IF(Data_input!O5="","",Data_input!O5) -> 45663 | Q5: =IF(P5="","",EDATE(P5,12)) -> 46028 | R5: =IF(Data_input!Q5="","",Data_input!Q5) -> 45875 | S5: =IF(I5="","",DATE(YEAR(I5)-1,MONTH(I5),DAY(I5))) -> 47119 | T5: =IF(LEN(TRIM(Data_input!P5))=0,"",Data_input!P5) -> 47340 | U5: =IF(I5="","",I5) -> 47484 | V5: =IF(G5="","", IF(ISNUMBER(SEARCH("Ph.D",M5)), EDATE(G5,24), EDATE(G5,15))) -> 46392 | W5: =IF(Data_input!R5="","",Data_input!R5) -> 46239 | X5: =IF(Data_input!S5="","",Data_input!S5) -> 46248
A6: =IF(Data_input!A6="","",Data_input!A6) -> 247R7 | B6: =IF(Data_input!B6="","",Data_input!B6) -> 250PA247R7 | C6: =IF(Data_input!C6="","",Data_input!C6) -> NUHU DAN-AZUMI MUHAMMAD | D6: =IF(Data_input!D6="","",Data_input!D6) -> Active in Program | E6: =IF(Data_input!E6="","",Data_input!E6) -> MATR | F6: =IF(Data_input!F6="","",Data_input!F6) -> 2500 | G6: =IF(Data_input!G6="","",Data_input!G6) -> 45662 | H6: =IF(Data_input!H6="","",Data_input!H6) -> 45658 | I6: =IF(OR(H6="",L6=""),"", IF(ISNUMBER(SEARCH("Ph.D",M6)), IF(L6="Full-Time",EDATE(H6,12*5),EDATE(H6,12*7)), IF(L6="Full-Time",EDATE(H6,12*3),EDATE(H6,12*5)) )) -> 47484 | J6: =IF(Data_input!I6="","",Data_input!I6) -> 3000 | K6: =IF(Data_input!J6="","",Data_input!J6) -> CYBER | L6: =IF(Data_input!K6="","",Data_input!K6) -> Full-Time | M6: =IF(Data_input!L6="","",Data_input!L6) -> Ph.D. (Eng) | N6: =IF(Data_input!M6="","",Data_input!M6) -> Doctor of Philosophy (Engineering) | O6: =IF(Data_input!N6="","",Data_input!N6) -> Faculty of AI and Engineering | P6: =IF(Data_input!O6="","",Data_input!O6) -> 45663 | Q6: =IF(P6="","",EDATE(P6,12)) -> 46028 | R6: =IF(Data_input!Q6="","",Data_input!Q6) -> 45875 | S6: =IF(I6="","",DATE(YEAR(I6)-1,MONTH(I6),DAY(I6))) -> 47119 | T6: =IF(LEN(TRIM(Data_input!P6))=0,"",Data_input!P6) -> 47346 | U6: =IF(I6="","",I6) -> 47484 | V6: =IF(G6="","", IF(ISNUMBER(SEARCH("Ph.D",M6)), EDATE(G6,24), EDATE(G6,15))) -> 46392 | W6: =IF(Data_input!R6="","",Data_input!R6) -> 46240 | X6: =IF(Data_input!S6="","",Data_input!S6) -> 46249
A7: =IF(Data_input!A7="","",Data_input!A7) -> 2508F | B7: =IF(Data_input!B7="","",Data_input!B7) -> 250PA257R3 | C7: =IF(Data_input!C7="","",Data_input!C7) -> NAZ ANUM | D7: =IF(Data_input!D7="","",Data_input!D7) -> Active in Program | E7: =IF(Data_input!E7="","",Data_input!E7) -> MATR | F7: =IF(Data_input!F7="","",Data_input!F7) -> 2500 | G7: =IF(Data_input!G7="","",Data_input!G7) -> 45661 | H7: =IF(Data_input!H7="","",Data_input!H7) -> 45658 | I7: =IF(OR(H7="",L7=""),"", IF(ISNUMBER(SEARCH("Ph.D",M7)), IF(L7="Full-Time",EDATE(H7,12*5),EDATE(H7,12*7)), IF(L7="Full-Time",EDATE(H7,12*3),EDATE(H7,12*5)) )) -> 47484 | J7: =IF(Data_input!I7="","",Data_input!I7) -> 3000 | K7: =IF(Data_input!J7="","",Data_input!J7) -> CYBER | L7: =IF(Data_input!K7="","",Data_input!K7) -> Full-Time | M7: =IF(Data_input!L7="","",Data_input!L7) -> Ph.D. (Eng) | N7: =IF(Data_input!M7="","",Data_input!M7) -> Doctor of Philosophy (Engineering) | O7: =IF(Data_input!N7="","",Data_input!N7) -> Faculty of AI and Engineering | P7: =IF(Data_input!O7="","",Data_input!O7) -> 45662 | Q7: =IF(P7="","",EDATE(P7,12)) -> 46027 | R7: =IF(Data_input!Q7="","",Data_input!Q7) -> 45876 | S7: =IF(I7="","",DATE(YEAR(I7)-1,MONTH(I7),DAY(I7))) -> 47119 | T7: =IF(LEN(TRIM(Data_input!P7))=0,"",Data_input!P7) -> 47342 | U7: =IF(I7="","",I7) -> 47484 | V7: =IF(G7="","", IF(ISNUMBER(SEARCH("Ph.D",M7)), EDATE(G7,24), EDATE(G7,15))) -> 46391 | W7: =IF(Data_input!R7="","",Data_input!R7) -> 46241 | X7: =IF(Data_input!S7="","",Data_input!S7) -> 46250
A8: =IF(Data_input!A8="","",Data_input!A8) -> 243YN | B8: =IF(Data_input!B8="","",Data_input!B8) -> 250PA237R1 | C8: =IF(Data_input!C8="","",Data_input!C8) -> NUR SYAZA BINTI ZAKARIA | D8: =IF(Data_input!D8="","",Data_input!D8) -> Active in Program | E8: =IF(Data_input!E8="","",Data_input!E8) -> MATR | F8: =IF(Data_input!F8="","",Data_input!F8) -> 2500 | G8: =IF(Data_input!G8="","",Data_input!G8) -> 45695 | H8: =IF(Data_input!H8="","",Data_input!H8) -> 45658 | I8: =IF(OR(H8="",L8=""),"", IF(ISNUMBER(SEARCH("Ph.D",M8)), IF(L8="Full-Time",EDATE(H8,12*5),EDATE(H8,12*7)), IF(L8="Full-Time",EDATE(H8,12*3),EDATE(H8,12*5)) )) -> 47484 | J8: =IF(Data_input!I8="","",Data_input!I8) -> 3000 | K8: =IF(Data_input!J8="","",Data_input!J8) -> CYBER | L8: =IF(Data_input!K8="","",Data_input!K8) -> Full-Time | M8: =IF(Data_input!L8="","",Data_input!L8) -> Ph.D. (Eng) | N8: =IF(Data_input!M8="","",Data_input!M8) -> Doctor of Philosophy (Engineering) | O8: =IF(Data_input!N8="","",Data_input!N8) -> Faculty of AI and Engineering | P8: =IF(Data_input!O8="","",Data_input!O8) -> 45696 | Q8: =IF(P8="","",EDATE(P8,12)) -> 46061 | R8: =IF(Data_input!Q8="","",Data_input!Q8) -> 46242 | S8: =IF(I8="","",DATE(YEAR(I8)-1,MONTH(I8),DAY(I8))) -> 47119 | T8: =IF(LEN(TRIM(Data_input!P8))=0,"",Data_input!P8) -> 47496 | U8: =IF(I8="","",I8) -> 47484 | V8: =IF(G8="","", IF(ISNUMBER(SEARCH("Ph.D",M8)), EDATE(G8,24), EDATE(G8,15))) -> 46425 | W8: =IF(Data_input!R8="","",Data_input!R8) -> 46607 | X8: =IF(Data_input!S8="","",Data_input!S8) -> 46607
A9: =IF(Data_input!A9="","",Data_input!A9) -> 251D4 | B9: =IF(Data_input!B9="","",Data_input!B9) -> 250PK242QD | C9: =IF(Data_input!C9="","",Data_input!C9) -> YANG XIAO | D9: =IF(Data_input!D9="","",Data_input!D9) -> Active in Program | E9: =IF(Data_input!E9="","",Data_input!E9) -> MATR | F9: =IF(Data_input!F9="","",Data_input!F9) -> 2500 | G9: =IF(Data_input!G9="","",Data_input!G9) -> 45738 | H9: =IF(Data_input!H9="","",Data_input!H9) -> 45658 | I9: =IF(OR(H9="",L9=""),"", IF(ISNUMBER(SEARCH("Ph.D",M9)), IF(L9="Full-Time",EDATE(H9,12*5),EDATE(H9,12*7)), IF(L9="Full-Time",EDATE(H9,12*3),EDATE(H9,12*5)) )) -> 47484 | J9: =IF(Data_input!I9="","",Data_input!I9) -> 3000 | K9: =IF(Data_input!J9="","",Data_input!J9) -> CYBER | L9: =IF(Data_input!K9="","",Data_input!K9) -> Full-Time | M9: =IF(Data_input!L9="","",Data_input!L9) -> Ph.D. (Communication) | N9: =IF(Data_input!M9="","",Data_input!M9) -> Doctor of Philosophy (Communication) | O9: =IF(Data_input!N9="","",Data_input!N9) -> Faculty of Applied Comm | P9: =IF(Data_input!O9="","",Data_input!O9) -> 45739 | Q9: =IF(P9="","",EDATE(P9,12)) -> 46104 | R9: =IF(Data_input!Q9="","",Data_input!Q9) -> 46121 | S9: =IF(I9="","",DATE(YEAR(I9)-1,MONTH(I9),DAY(I9))) -> 47119 | T9: =IF(LEN(TRIM(Data_input!P9))=0,"",Data_input!P9) -> 47497 | U9: =IF(I9="","",I9) -> 47484 | V9: =IF(G9="","", IF(ISNUMBER(SEARCH("Ph.D",M9)), EDATE(G9,24), EDATE(G9,15))) -> 46468 | W9: =IF(Data_input!R9="","",Data_input!R9) -> 46608 | X9: =IF(Data_input!S9="","",Data_input!S9) -> 46610
A10: =IF(Data_input!A10="","",Data_input!A10) -> 2458H | B10: =IF(Data_input!B10="","",Data_input!B10) -> 250PK232QD | C10: =IF(Data_input!C10="","",Data_input!C10) -> MD MUSLIM UDDIN AHMED PIPUL | D10: =IF(Data_input!D10="","",Data_input!D10) -> Active in Program | E10: =IF(Data_input!E10="","",Data_input!E10) -> MATR | F10: =IF(Data_input!F10="","",Data_input!F10) -> 2500 | G10: =IF(Data_input!G10="","",Data_input!G10) -> 45724 | H10: =IF(Data_input!H10="","",Data_input!H10) -> 45658 | I10: =IF(OR(H10="",L10=""),"", IF(ISNUMBER(SEARCH("Ph.D",M10)), IF(L10="Full-Time",EDATE(H10,12*5),EDATE(H10,12*7)), IF(L10="Full-Time",EDATE(H10,12*3),EDATE(H10,12*5)) )) -> 47484 | J10: =IF(Data_input!I10="","",Data_input!I10) -> 3000 | K10: =IF(Data_input!J10="","",Data_input!J10) -> CYBER | L10: =IF(Data_input!K10="","",Data_input!K10) -> Full-Time | M10: =IF(Data_input!L10="","",Data_input!L10) -> Ph.D. (Communication) | N10: =IF(Data_input!M10="","",Data_input!M10) -> Doctor of Philosophy (Communication) | O10: =IF(Data_input!N10="","",Data_input!N10) -> Faculty of Applied Comm | P10: =IF(Data_input!O10="","",Data_input!O10) -> 45725 | Q10: =IF(P10="","",EDATE(P10,12)) -> 46090 | R10: =IF(Data_input!Q10="","",Data_input!Q10) -> 46244 | S10: =IF(I10="","",DATE(YEAR(I10)-1,MONTH(I10),DAY(I10))) -> 47119 | T10: =IF(LEN(TRIM(Data_input!P10))=0,"",Data_input!P10) -> 47498 | U10: =IF(I10="","",I10) -> 47484 | V10: =IF(G10="","", IF(ISNUMBER(SEARCH("Ph.D",M10)), EDATE(G10,24), EDATE(G10,15))) -> 46454 | W10: =IF(Data_input!R10="","",Data_input!R10) -> 46609 | X10: =IF(Data_input!S10="","",Data_input!S10) -> 46609
A11: =IF(Data_input!A11="","",Data_input!A11) -> 252QD | B11: =IF(Data_input!B11="","",Data_input!B11) -> 250PK222QD | C11: =IF(Data_input!C11="","",Data_input!C11) -> JOANNA A/P JAYAPRAKASH | D11: =IF(Data_input!D11="","",Data_input!D11) -> Active in Program | E11: =IF(Data_input!E11="","",Data_input!E11) -> MATR | F11: =IF(Data_input!F11="","",Data_input!F11) -> 2500 | G11: =IF(Data_input!G11="","",Data_input!G11) -> 45704 | H11: =IF(Data_input!H11="","",Data_input!H11) -> 45658 | I11: =IF(OR(H11="",L11=""),"", IF(ISNUMBER(SEARCH("Ph.D",M11)), IF(L11="Full-Time",EDATE(H11,12*5),EDATE(H11,12*7)), IF(L11="Full-Time",EDATE(H11,12*3),EDATE(H11,12*5)) )) -> 47484 | J11: =IF(Data_input!I11="","",Data_input!I11) -> 3000 | K11: =IF(Data_input!J11="","",Data_input!J11) -> CYBER | L11: =IF(Data_input!K11="","",Data_input!K11) -> Full-Time | M11: =IF(Data_input!L11="","",Data_input!L11) -> Ph.D. (Communication) | N11: =IF(Data_input!M11="","",Data_input!M11) -> Doctor of Philosophy (Communication) | O11: =IF(Data_input!N11="","",Data_input!N11) -> Faculty of Applied Comm | P11: =IF(Data_input!O11="","",Data_input!O11) -> 45705 | Q11: =IF(P11="","",EDATE(P11,12)) -> 46070 | R11: =IF(Data_input!Q11="","",Data_input!Q11) -> 46245 | S11: =IF(I11="","",DATE(YEAR(I11)-1,MONTH(I11),DAY(I11))) -> 47119 | T11: =IF(LEN(TRIM(Data_input!P11))=0,"",Data_input!P11) -> 47499 | U11: =IF(I11="","",I11) -> 47484 | V11: =IF(G11="","", IF(ISNUMBER(SEARCH("Ph.D",M11)), EDATE(G11,24), EDATE(G11,15))) -> 46434 | W11: =IF(Data_input!R11="","",Data_input!R11) -> 46610 | X11: =IF(Data_input!S11="","",Data_input!S11) -> 46610
A12: =IF(Data_input!A12="","",Data_input!A12) -> 243YN | B12: =IF(Data_input!B12="","",Data_input!B12) -> 250PK212QD | C12: =IF(Data_input!C12="","",Data_input!C12) -> HAMZA BASHER ALAMIN BARKA | D12: =IF(Data_input!D12="","",Data_input!D12) -> Active in Program | E12: =IF(Data_input!E12="","",Data_input!E12) -> MATR | F12: =IF(Data_input!F12="","",Data_input!F12) -> 2500 | G12: =IF(Data_input!G12="","",Data_input!G12) -> 45662 | H12: =IF(Data_input!H12="","",Data_input!H12) -> 45658 | I12: =IF(OR(H12="",L12=""),"", IF(ISNUMBER(SEARCH("Ph.D",M12)), IF(L12="Full-Time",EDATE(H12,12*5),EDATE(H12,12*7)), IF(L12="Full-Time",EDATE(H12,12*3),EDATE(H12,12*5)) )) -> 48214 | J12: =IF(Data_input!I12="","",Data_input!I12) -> 3000 | K12: =IF(Data_input!J12="","",Data_input!J12) -> CYBER | L12: =IF(Data_input!K12="","",Data_input!K12) -> Part-Time | M12: =IF(Data_input!L12="","",Data_input!L12) -> Ph.D. (Communication) | N12: =IF(Data_input!M12="","",Data_input!M12) -> Doctor of Philosophy (Communication) | O12: =IF(Data_input!N12="","",Data_input!N12) -> Faculty of Applied Comm | P12: =IF(Data_input!O12="","",Data_input!O12) -> 45663 | Q12: =IF(P12="","",EDATE(P12,12)) -> 46028 | R12: =IF(Data_input!Q12="","",Data_input!Q12) -> 45795 | S12: =IF(I12="","",DATE(YEAR(I12)-1,MONTH(I12),DAY(I12))) -> 47849 | T12: =IF(LEN(TRIM(Data_input!P12))=0,"",Data_input!P12) -> 47225 | U12: =IF(I12="","",I12) -> 48214 | V12: =IF(G12="","", IF(ISNUMBER(SEARCH("Ph.D",M12)), EDATE(G12,24), EDATE(G12,15))) -> 46392 | W12: =IF(Data_input!R12="","",Data_input!R12) -> 45759 | X12: =IF(Data_input!S12="","",Data_input!S12) -> 45759
A13: =IF(Data_input!A13="","",Data_input!A13) -> 247R7 | B13: =IF(Data_input!B13="","",Data_input!B13) -> 250PK272QD | C13: =IF(Data_input!C13="","",Data_input!C13) -> NAHIDA FERDOUS | D13: =IF(Data_input!D13="","",Data_input!D13) -> Active in Program | E13: =IF(Data_input!E13="","",Data_input!E13) -> MATR | F13: =IF(Data_input!F13="","",Data_input!F13) -> 2500 | G13: =IF(Data_input!G13="","",Data_input!G13) -> 45695 | H13: =IF(Data_input!H13="","",Data_input!H13) -> 45658 | I13: =IF(OR(H13="",L13=""),"", IF(ISNUMBER(SEARCH("Ph.D",M13)), IF(L13="Full-Time",EDATE(H13,12*5),EDATE(H13,12*7)), IF(L13="Full-Time",EDATE(H13,12*3),EDATE(H13,12*5)) )) -> 48214 | J13: =IF(Data_input!I13="","",Data_input!I13) -> 3000 | K13: =IF(Data_input!J13="","",Data_input!J13) -> CYBER | L13: =IF(Data_input!K13="","",Data_input!K13) -> Part-Time | M13: =IF(Data_input!L13="","",Data_input!L13) -> Ph.D. (Communication) | N13: =IF(Data_input!M13="","",Data_input!M13) -> Doctor of Philosophy (Communication) | O13: =IF(Data_input!N13="","",Data_input!N13) -> Faculty of Applied Comm | P13: =IF(Data_input!O13="","",Data_input!O13) -> 45696 | Q13: =IF(P13="","",EDATE(P13,12)) -> 46061 | R13: =IF(Data_input!Q13="","",Data_input!Q13) -> 45765 | S13: =IF(I13="","",DATE(YEAR(I13)-1,MONTH(I13),DAY(I13))) -> 47849 | T13: =IF(LEN(TRIM(Data_input!P13))=0,"",Data_input!P13) -> 47226 | U13: =IF(I13="","",I13) -> 48214 | V13: =IF(G13="","", IF(ISNUMBER(SEARCH("Ph.D",M13)), EDATE(G13,24), EDATE(G13,15))) -> 46425 | W13: =IF(Data_input!R13="","",Data_input!R13) -> 46125 | X13: =IF(Data_input!S13="","",Data_input!S13) -> 46135
... A59: =IF(Data_input!A59="","",Data_input!A59) | B59: =IF(Data_input!B59="","",Data_input!B59) | C59: =IF(Data_input!C59="","",Data_input!C59) | D59: =IF(Data_input!D59="","",Data_input!D59) | E59: =IF(Data_input!E59="","",Data_input!E59) | F59: =IF(Data_input!F59="","",Data_input!F59) | G59: =IF(Data_input!G59="","",Data_input!G59) | H59: =IF(Data_input!H59="","",Data_input!H59) | I59: =IF(OR(H59="",L59=""),"", IF(ISNUMBER(SEARCH("Ph.D",M59)), IF(L59="Full-Time",EDATE(H59,12*5),EDATE(H59,12*7)), IF(L59="Full-Time",EDATE(H59,12*3),EDATE(H59,12*5)) )) | J59: =IF(Data_input!I59="","",Data_input!I59) | K59: =IF(Data_input!J59="","",Data_input!J59) | L59: =IF(Data_input!K59="","",Data_input!K59) | M59: =IF(Data_input!L59="","",Data_input!L59) | N59: =IF(Data_input!M59="","",Data_input!M59) | O59: =IF(Data_input!N59="","",Data_input!N59) | P59: =IF(Data_input!O59="","",Data_input!O59) | Q59: =IF(P59="","",EDATE(P59,12)) | R59: =IF(Data_input!Q59="","",Data_input!Q59) | S59: =IF(I59="","",DATE(YEAR(I59)-1,MONTH(I59),DAY(I59))) | T59: =IF(LEN(TRIM(Data_input!P59))=0,"",Data_input!P59) | U59: =IF(I59="","",I59) | V59: =IF(G59="","", IF(ISNUMBER(SEARCH("Ph.D",M59)), EDATE(G59,24), EDATE(G59,15))) | W59: =IF(Data_input!R59="","",Data_input!R59) | X59: =IF(Data_input!S59="","",Data_input!S59)
A60: =IF(Data_input!A60="","",Data_input!A60) | B60: =IF(Data_input!B60="","",Data_input!B60) | C60: =IF(Data_input!C60="","",Data_input!C60) | D60: =IF(Data_input!D60="","",Data_input!D60) | E60: =IF(Data_input!E60="","",Data_input!E60) | F60: =IF(Data_input!F60="","",Data_input!F60) | G60: =IF(Data_input!G60="","",Data_input!G60) | H60: =IF(Data_input!H60="","",Data_input!H60) | I60: =IF(OR(H60="",L60=""),"",IF(L60="Full-Time",EDATE(H60,12*5),EDATE(H60,12*7))) | J60: =IF(Data_input!I60="","",Data_input!I60) | K60: =IF(Data_input!J60="","",Data_input!J60) | L60: =IF(Data_input!K60="","",Data_input!K60) | M60: =IF(Data_input!L60="","",Data_input!L60) | N60: =IF(Data_input!M60="","",Data_input!M60) | O60: =IF(Data_input!N60="","",Data_input!N60) | P60: =IF(Data_input!O60="","",Data_input!O60) | Q60: =IF(P60="","",EDATE(P60,12)) | R60: =IF(Data_input!Q60="","",Data_input!Q60) | S60: =IF(I60="","",DATE(YEAR(I60)-1,MONTH(I60),DAY(I60))) | T60: =IF(LEN(TRIM(Data_input!P60))=0,"",Data_input!P60) | U60: =IF(I60="","",I60) | V60: =IF(G60="","", IF(ISNUMBER(SEARCH("Ph.D",M60)), EDATE(G60,24), EDATE(G60,15))) | W60: =IF(Data_input!R60="","",Data_input!R60) | X60: =IF(Data_input!S60="","",Data_input!S60)
A61: =IF(Data_input!A61="","",Data_input!A61) | J61: =IF(Data_input!I61="","",Data_input!I61)
A62: =IF(Data_input!A62="","",Data_input!A62)
A63: =IF(Data_input!A63="","",Data_input!A63)
A64: =IF(Data_input!A64="","",Data_input!A64)
A65: =IF(Data_input!A65="","",Data_input!A65)
A66: =IF(Data_input!A66="","",Data_input!A66)

Sheet PPM_Student
A1: CAMPUS_ID | B1: Student_ID | C1: Name | D1: Prog_short_Des | E1: PPM_Jun2025 | F1: PPM_Dec2025 | G1: PPM_Jun2026 | H1: PPM_Dec2026 | I1: PPM_Jun2027 | J1: PPM_Dec2027 | K1: PPM_Jun2028 | L1: PPM_Dec2028 | M1: PPM_Jun2029 | N1: PPM_Dec2029 | O1: PPM_Jun2030 | P1: PPM_Dec2030 | Q1: PPM_Jun2031 | R1: PPM_Dec2031 | S1: PPM_Jun2032 | T1: PPM_Dec2032 | U1: Mark_PPM
A2: =IF(Data_input!A2="","",Data_input!A2) -> 247R1 | B2: =IF(Data_input!B2="","",Data_input!B2) -> 250PA247R8 | C2: =IF(Data_input!C2="","",Data_input!C2) -> USMAN YAU | D2: =IF(Data_input!L2="","",Data_input!L2) -> Ph.D. (Eng) | E2: S | F2: S | G2: S | H2: S | I2: S | J2: S | K2: S | L2: S | M2: S | N2: S | O2: S | P2: S | U2: =IF(A2="","", IF(COUNTIF(E2:T2,"US")>=3,0, 10-COUNTIF(E2:T2,"US"))) -> 10
A3: =IF(Data_input!A3="","",Data_input!A3) -> 247R4 | B3: =IF(Data_input!B3="","",Data_input!B3) -> 250PA247R1 | C3: =IF(Data_input!C3="","",Data_input!C3) -> KHAN IRFAN | D3: =IF(Data_input!L3="","",Data_input!L3) -> Ph.D. (Eng) | E3: NA | F3: S | G3: S | H3: S | I3: S | J3: S | K3: S | L3: S | M3: S | N3: S | O3: S | P3: S | U3: =IF(A3="","", IF(COUNTIF(E3:T3,"US")>=3,0, 10-COUNTIF(E3:T3,"US"))) -> 10
A4: =IF(Data_input!A4="","",Data_input!A4) -> 247R8 | B4: =IF(Data_input!B4="","",Data_input!B4) -> 250PA247R2 | C4: =IF(Data_input!C4="","",Data_input!C4) -> JAYAKANTHAN A/L M. LACHMANAN | D4: =IF(Data_input!L4="","",Data_input!L4) -> Ph.D. (Eng) | E4: US | F4: US | G4: S | H4: S | I4: S | J4: S | K4: S | L4: S | M4: S | N4: S | O4: S | P4: S | U4: =IF(A4="","", IF(COUNTIF(E4:T4,"US")>=3,0, 10-COUNTIF(E4:T4,"US"))) -> 8
A5: =IF(Data_input!A5="","",Data_input!A5) -> 247R3 | B5: =IF(Data_input!B5="","",Data_input!B5) -> 250PA247R5 | C5: =IF(Data_input!C5="","",Data_input!C5) -> IDRIS OLALEKAN ADEOYE | D5: =IF(Data_input!L5="","",Data_input!L5) -> Ph.D. (Eng) | E5: S | F5: S | G5: S | H5: S | I5: S | J5: S | K5: S | L5: S | M5: S | N5: S | O5: S | P5: S | U5: =IF(A5="","", IF(COUNTIF(E5:T5,"US")>=3,0, 10-COUNTIF(E5:T5,"US"))) -> 10
A6: =IF(Data_input!A6="","",Data_input!A6) -> 247R7 | B6: =IF(Data_input!B6="","",Data_input!B6) -> 250PA247R7 | C6: =IF(Data_input!C6="","",Data_input!C6) -> NUHU DAN-AZUMI MUHAMMAD | D6: =IF(Data_input!L6="","",Data_input!L6) -> Ph.D. (Eng) | E6: S | F6: S | G6: S | H6: S | I6: S | J6: S | K6: S | L6: S | M6: NA | N6: S | O6: S | P6: S | U6: =IF(A6="","", IF(COUNTIF(E6:T6,"US")>=3,0, 10-COUNTIF(E6:T6,"US"))) -> 10
A7: =IF(Data_input!A7="","",Data_input!A7) -> 2508F | B7: =IF(Data_input!B7="","",Data_input!B7) -> 250PA257R3 | C7: =IF(Data_input!C7="","",Data_input!C7) -> NAZ ANUM | D7: =IF(Data_input!L7="","",Data_input!L7) -> Ph.D. (Eng) | E7: S | F7: S | G7: S | H7: S | I7: S | J7: S | K7: S | L7: S | M7: S | N7: S | O7: S | P7: S | U7: =IF(A7="","", IF(COUNTIF(E7:T7,"US")>=3,0, 10-COUNTIF(E7:T7,"US"))) -> 10
A8: =IF(Data_input!A8="","",Data_input!A8) -> 243YN | B8: =IF(Data_input!B8="","",Data_input!B8) -> 250PA237R1 | C8: =IF(Data_input!C8="","",Data_input!C8) -> NUR SYAZA BINTI ZAKARIA | D8: =IF(Data_input!L8="","",Data_input!L8) -> Ph.D. (Eng) | E8: US | F8: S | G8: S | H8: US | I8: S | J8: S | K8: US | L8: S | M8: S | N8: S | O8: S | P8: S | U8: =IF(A8="","", IF(COUNTIF(E8:T8,"US")>=3,0, 10-COUNTIF(E8:T8,"US"))) -> 0
A9: =IF(Data_input!A9="","",Data_input!A9) -> 251D4 | B9: =IF(Data_input!B9="","",Data_input!B9) -> 250PK242QD | C9: =IF(Data_input!C9="","",Data_input!C9) -> YANG XIAO | D9: =IF(Data_input!L9="","",Data_input!L9) -> Ph.D. (Communication) | E9: US | F9: S | G9: S | H9: US | I9: S | J9: S | K9: US | L9: S | M9: S | N9: S | O9: S | P9: S | U9: =IF(A9="","", IF(COUNTIF(E9:T9,"US")>=3,0, 10-COUNTIF(E9:T9,"US"))) -> 0
A10: =IF(Data_input!A10="","",Data_input!A10) -> 2458H | B10: =IF(Data_input!B10="","",Data_input!B10) -> 250PK232QD | C10: =IF(Data_input!C10="","",Data_input!C10) -> MD MUSLIM UDDIN AHMED PIPUL | D10: =IF(Data_input!L10="","",Data_input!L10) -> Ph.D. (Communication) | E10: US | F10: S | G10: S | H10: US | I10: S | J10: US | K10: S | L10: S | M10: S | N10: S | O10: S | P10: S | U10: =IF(A10="","", IF(COUNTIF(E10:T10,"US")>=3,0, 10-COUNTIF(E10:T10,"US"))) -> 0
A11: =IF(Data_input!A11="","",Data_input!A11) -> 252QD | B11: =IF(Data_input!B11="","",Data_input!B11) -> 250PK222QD | C11: =IF(Data_input!C11="","",Data_input!C11) -> JOANNA A/P JAYAPRAKASH | D11: =IF(Data_input!L11="","",Data_input!L11) -> Ph.D. (Communication) | E11: S | F11: S | G11: S | H11: US | I11: US | J11: US | K11: S | L11: S | M11: S | N11: S | O11: S | P11: S | Q11: S | R11: S | S11: S | T11: S | U11: =IF(A11="","", IF(COUNTIF(E11:T11,"US")>=3,0, 10-COUNTIF(E11:T11,"US"))) -> 0
A12: =IF(Data_input!A12="","",Data_input!A12) -> 243YN | B12: =IF(Data_input!B12="","",Data_input!B12) -> 250PK212QD | C12: =IF(Data_input!C12="","",Data_input!C12) -> HAMZA BASHER ALAMIN BARKA | D12: =IF(Data_input!L12="","",Data_input!L12) -> Ph.D. (Communication) | E12: S | F12: S | G12: S | H12: S | I12: S | J12: S | K12: S | L12: S | M12: S | N12: S | O12: S | P12: S | Q12: S | R12: S | S12: S | T12: S | U12: =IF(A12="","", IF(COUNTIF(E12:T12,"US")>=3,0, 10-COUNTIF(E12:T12,"US"))) -> 10
A13: =IF(Data_input!A13="","",Data_input!A13) -> 247R7 | B13: =IF(Data_input!B13="","",Data_input!B13) -> 250PK272QD | C13: =IF(Data_input!C13="","",Data_input!C13) -> NAHIDA FERDOUS | D13: =IF(Data_input!L13="","",Data_input!L13) -> Ph.D. (Communication) | E13: S | F13: S | G13: S | H13: S | I13: S | J13: S | K13: S | L13: S | M13: S | N13: S | O13: S | P13: S | Q13: S | R13: S | S13: S | T13: S | U13: =IF(A13="","", IF(COUNTIF(E13:T13,"US")>=3,0, 10-COUNTIF(E13:T13,"US"))) -> 10
A14: =IF(Data_input!A14="","",Data_input!A14) -> 2458H | B14: =IF(Data_input!B14="","",Data_input!B14) -> 250PK251QD | C14: =IF(Data_input!C14="","",Data_input!C14) -> NAHIDA ANUM | D14: =IF(Data_input!L14="","",Data_input!L14) -> Ph.D. (Communication) | E14: S | F14: S | G14: S | H14: S | I14: S | J14: S | K14: S | L14: S | M14: S | N14: S | O14: S | P14: S | Q14: S | R14: S | S14: S | T14: S | U14: =IF(A14="","", IF(COUNTIF(E14:T14,"US")>=3,0, 10-COUNTIF(E14:T14,"US"))) -> 10
A15: =IF(Data_input!A15="","",Data_input!A15) -> 245YK | B15: =IF(Data_input!B15="","",Data_input!B15) -> 250PB252PD | C15: =IF(Data_input!C15="","",Data_input!C15) -> KHAN FERDOUS | D15: =IF(Data_input!L15="","",Data_input!L15) -> Ph.D. (Mgmt.) | E15: S | F15: S | G15: S | H15: S | I15: S | J15: S | K15: S | L15: S | M15: US | N15: S | O15: S | P15: S | Q15: S | R15: S | S15: S | T15: S | U15: =IF(A15="","", IF(COUNTIF(E15:T15,"US")>=3,0, 10-COUNTIF(E15:T15,"US"))) -> 9
A16: =IF(Data_input!A16="","",Data_input!A16) -> 245ZK | B16: =IF(Data_input!B16="","",Data_input!B16) -> 250PB244PD | C16: =IF(Data_input!C16="","",Data_input!C16) -> PUARA A/P LACHMANAN | D16: =IF(Data_input!L16="","",Data_input!L16) -> Ph.D. (Mgmt.) | E16: S | F16: S | G16: S | H16: S | I16: S | J16: S | K16: S | L16: US | M16: S | N16: S | O16: S | P16: S | Q16: S | R16: S | S16: S | T16: S | U16: =IF(A16="","", IF(COUNTIF(E16:T16,"US")>=3,0, 10-COUNTIF(E16:T16,"US"))) -> 9
A17: =IF(Data_input!A17="","",Data_input!A17) -> 245RK | B17: =IF(Data_input!B17="","",Data_input!B17) -> 250PB258PD | C17: =IF(Data_input!C17="","",Data_input!C17) -> YONG YU KIN | D17: =IF(Data_input!L17="","",Data_input!L17) -> Ph.D. (Mgmt.) | E17: S | F17: S | G17: NA | H17: S | I17: S | J17: S | K17: S | L17: US | M17: US | N17: S | O17: S | P17: S | Q17: S | R17: S | S17: S | T17: S | U17: =IF(A17="","", IF(COUNTIF(E17:T17,"US")>=3,0, 10-COUNTIF(E17:T17,"US"))) -> 8
A18: =IF(Data_input!A18="","",Data_input!A18) -> 247R7 | B18: =IF(Data_input!B18="","",Data_input!B18) -> 250PB259PD | C18: =IF(Data_input!C18="","",Data_input!C18) -> WONG KIN HUAT | D18: =IF(Data_input!L18="","",Data_input!L18) -> Ph.D. (Mgmt.) | E18: S | F18: S | G18: S | H18: S | I18: NA | J18: S | K18: S | L18: NA | M18: S | N18: S | O18: S | P18: S | Q18: S | R18: S | S18: S | T18: S | U18: =IF(A18="","", IF(COUNTIF(E18:T18,"US")>=3,0, 10-COUNTIF(E18:T18,"US"))) -> 10
A19: =IF(Data_input!A19="","",Data_input!A19) -> 247R8 | B19: =IF(Data_input!B19="","",Data_input!B19) -> 250PB260PD | C19: =IF(Data_input!C19="","",Data_input!C19) -> WONG KANG JUN | D19: =IF(Data_input!L19="","",Data_input!L19) -> Ph.D. (Mgmt.) | E19: S | F19: S | G19: S | H19: S | I19: S | J19: S | K19: S | L19: S | M19: S | N19: S | O19: S | P19: S | Q19: US | R19: US | S19: US | U19: =IF(A19="","", IF(COUNTIF(E19:T19,"US")>=3,0, 10-COUNTIF(E19:T19,"US"))) -> 0
A20: =IF(Data_input!A20="","",Data_input!A20) -> 247R9 | B20: =IF(Data_input!B20="","",Data_input!B20) -> 250PA213RK | C20: =IF(Data_input!C20="","",Data_input!C20) -> AHMAD FAISAL BIN YUSOF | D20: =IF(Data_input!L20="","",Data_input!L20) -> Ph.D. (Mgmt.) | E20: S | F20: S | G20: S | H20: S | I20: S | J20: S | K20: S | L20: S | M20: S | N20: S | O20: S | P20: S | Q20: US | R20: US | S20: US | U20: =IF(A20="","", IF(COUNTIF(E20:T20,"US")>=3,0, 10-COUNTIF(E20:T20,"US"))) -> 0
A21: =IF(Data_input!A21="","",Data_input!A21) -> 243A9 | B21: =IF(Data_input!B21="","",Data_input!B21) -> 250PK245T1 | C21: =IF(Data_input!C21="","",Data_input!C21) -> HANG JIA YEE | D21: =IF(Data_input!L21="","",Data_input!L21) -> Master (Mgmt) | E21: S | F21: S | G21: S | H21: S | I21: S | J21: S | K21: S | L21: S | M21: S | N21: S | O21: S | P21: S | Q21: US | R21: US | S21: US | U21: =IF(A21="","", IF(COUNTIF(E21:T21,"US")>=3,0, 10-COUNTIF(E21:T21,"US"))) -> 0
A22: =IF(Data_input!A22="","",Data_input!A22) -> 248RK | B22: =IF(Data_input!B22="","",Data_input!B22) -> 250PH272RM | C22: =IF(Data_input!C22="","",Data_input!C22) -> LEE KOK MING | D22: =IF(Data_input!L22="","",Data_input!L22) -> Master (Mgmt) | E22: S | F22: S | G22: S | H22: S | I22: S | J22: S | K22: S | L22: S | U22: =IF(A22="","", IF(COUNTIF(E22:T22,"US")>=3,0, 10-COUNTIF(E22:T22,"US"))) -> 10
A23: =IF(Data_input!A23="","",Data_input!A23) -> 249YH | B23: =IF(Data_input!B23="","",Data_input!B23) -> 250PN281Q2 | C23: =IF(Data_input!C23="","",Data_input!C23) -> SITI NUR AIN BINTI RAHMAN | D23: =IF(Data_input!L23="","",Data_input!L23) -> Master (Mgmt) | E23: S | F23: S | G23: S | H23: S | I23: S | J23: S | K23: S | L23: S | U23: =IF(A23="","", IF(COUNTIF(E23:T23,"US")>=3,0, 10-COUNTIF(E23:T23,"US"))) -> 10
A24: =IF(Data_input!A24="","",Data_input!A24) -> 2468Z | B24: =IF(Data_input!B24="","",Data_input!B24) -> 250PM269QD | C24: =IF(Data_input!C24="","",Data_input!C24) -> RAHUL KUMAR SINGH | D24: =IF(Data_input!L24="","",Data_input!L24) -> Master (Mgmt) | E24: S | F24: S | G24: S | H24: S | I24: S | J24: S | K24: S | L24: S | U24: =IF(A24="","", IF(COUNTIF(E24:T24,"US")>=3,0, 10-COUNTIF(E24:T24,"US"))) -> 10
A25: =IF(Data_input!A25="","",Data_input!A25) -> 247JK | B25: =IF(Data_input!B25="","",Data_input!B25) -> 250PJ258RD | C25: =IF(Data_input!C25="","",Data_input!C25) -> CHAN WEI HONG | D25: =IF(Data_input!L25="","",Data_input!L25) -> Master (Law) | E25: S | F25: S | G25: S | H25: S | I25: US | J25: S | K25: US | L25: S | U25: =IF(A25="","", IF(COUNTIF(E25:T25,"US")>=3,0, 10-COUNTIF(E25:T25,"US"))) -> 8
A26: =IF(Data_input!A26="","",Data_input!A26) -> 245PL | B26: =IF(Data_input!B26="","",Data_input!B26) -> 250PL293T1 | C26: =IF(Data_input!C26="","",Data_input!C26) -> NURUL HUDA BINTI AZIZ | D26: =IF(Data_input!L26="","",Data_input!L26) -> Master (Law) | E26: S | F26: S | G26: S | H26: US | I26: S | J26: S | K26: US | L26: S | U26: =IF(A26="","", IF(COUNTIF(E26:T26,"US")>=3,0, 10-COUNTIF(E26:T26,"US"))) -> 8
A27: =IF(Data_input!A27="","",Data_input!A27) -> 244XM | B27: =IF(Data_input!B27="","",Data_input!B27) -> 250PR241PD | C27: =IF(Data_input!C27="","",Data_input!C27) -> MOHAMMAD ALI KHAN | D27: =IF(Data_input!L27="","",Data_input!L27) -> Master (Law) | E27: S | F27: S | G27: S | H27: S | I27: S | J27: US | K27: S | L27: S | U27: =IF(A27="","", IF(COUNTIF(E27:T27,"US")>=3,0, 10-COUNTIF(E27:T27,"US"))) -> 9
A28: =IF(Data_input!A28="","",Data_input!A28) -> 2495N | B28: =IF(Data_input!B28="","",Data_input!B28) -> 250PB237QK | C28: =IF(Data_input!C28="","",Data_input!C28) -> TAN JIA WEI | D28: =IF(Data_input!L28="","",Data_input!L28) -> Master (Law) | E28: S | F28: US | G28: US | H28: US | I28: S | J28: S | K28: S | L28: S | U28: =IF(A28="","", IF(COUNTIF(E28:T28,"US")>=3,0, 10-COUNTIF(E28:T28,"US"))) -> 0
A29: =IF(Data_input!A29="","",Data_input!A29) -> 246ZP | B29: =IF(Data_input!B29="","",Data_input!B29) -> 250PC276R2 | C29: =IF(Data_input!C29="","",Data_input!C29) -> FARHAN BIN ISMAIL | D29: =IF(Data_input!L29="","",Data_input!L29) -> Master (Law) | E29: US | F29: S | G29: US | H29: US | I29: S | J29: S | K29: S | L29: S | U29: =IF(A29="","", IF(COUNTIF(E29:T29,"US")>=3,0, 10-COUNTIF(E29:T29,"US"))) -> 0
A30: =IF(Data_input!A30="","",Data_input!A30) -> 247QR | B30: =IF(Data_input!B30="","",Data_input!B30) -> 250PE261RJ | C30: =IF(Data_input!C30="","",Data_input!C30) -> LIM PEI YEE | D30: =IF(Data_input!L30="","",Data_input!L30) -> Master (Mgmt) | E30: US | F30: S | G30: US | H30: US | I30: S | J30: NA | K30: S | L30: S | U30: =IF(A30="","", IF(COUNTIF(E30:T30,"US")>=3,0, 10-COUNTIF(E30:T30,"US"))) -> 0
A31: =IF(Data_input!A31="","",Data_input!A31) -> 248R7 | B31: =IF(Data_input!B31="","",Data_input!B31) -> 250PG248PD | C31: =IF(Data_input!C31="","",Data_input!C31) -> RAJESH PRASAD | D31: =IF(Data_input!L31="","",Data_input!L31) -> Master (Mgmt) | E31: S | F31: S | G31: S | H31: S | I31: S | J31: S | K31: S | L31: S | M31: S | N31: S | O31: S | U31: =IF(A31="","", IF(COUNTIF(E31:T31,"US")>=3,0, 10-COUNTIF(E31:T31,"US"))) -> 10
A32: =IF(Data_input!A32="","",Data_input!A32) -> 2458T | B32: =IF(Data_input!B32="","",Data_input!B32) -> 250PH234RM | C32: =IF(Data_input!C32="","",Data_input!C32) -> GOH MUN KIT | D32: =IF(Data_input!L32="","",Data_input!L32) -> Master (Mgmt) | E32: S | F32: S | G32: S | H32: S | I32: S | J32: S | K32: S | L32: S | M32: S | N32: S | O32: S | U32: =IF(A32="","", IF(COUNTIF(E32:T32,"US")>=3,0, 10-COUNTIF(E32:T32,"US"))) -> 10
A33: =IF(Data_input!A33="","",Data_input!A33) -> 2465K | B33: =IF(Data_input!B33="","",Data_input!B33) -> 250PJ285Q1 | C33: =IF(Data_input!C33="","",Data_input!C33) -> AISHA BINTI HASSAN | D33: =IF(Data_input!L33="","",Data_input!L33) -> Master (Mgmt) | E33: S | F33: S | G33: S | H33: S | I33: S | J33: S | K33: S | L33: S | M33: S | N33: S | O33: S | U33: =IF(A33="","", IF(COUNTIF(E33:T33,"US")>=3,0, 10-COUNTIF(E33:T33,"US"))) -> 10
A34: =IF(Data_input!A34="","",Data_input!A34) -> 247ZK | B34: =IF(Data_input!B34="","",Data_input!B34) -> 250PK292RD | C34: =IF(Data_input!C34="","",Data_input!C34) -> ONG JUN HAO | D34: =IF(Data_input!L34="","",Data_input!L34) -> Master (Law) | E34: S | F34: S | G34: S | H34: S | I34: S | J34: S | K34: S | L34: S | M34: S | N34: S | O34: S | U34: =IF(A34="","", IF(COUNTIF(E34:T34,"US")>=3,0, 10-COUNTIF(E34:T34,"US"))) -> 10
A35: =IF(Data_input!A35="","",Data_input!A35) -> 249PK | B35: =IF(Data_input!B35="","",Data_input!B35) -> 250PL239R2 | C35: =IF(Data_input!C35="","",Data_input!C35) -> PRIYA DEVI NAIR | D35: =IF(Data_input!L35="","",Data_input!L35) -> Master (Law) | E35: S | F35: S | G35: S | H35: S | I35: S | J35: S | K35: S | L35: S | M35: S | N35: S | O35: US | U35: =IF(A35="","", IF(COUNTIF(E35:T35,"US")>=3,0, 10-COUNTIF(E35:T35,"US"))) -> 9
A36: =IF(Data_input!A36="","",Data_input!A36) -> 243YK | B36: =IF(Data_input!B36="","",Data_input!B36) -> 250PN278QD | C36: =IF(Data_input!C36="","",Data_input!C36) -> CHONG KAI LUN | D36: =IF(Data_input!L36="","",Data_input!L36) -> Master (Law) | E36: S | F36: S | G36: S | H36: S | I36: S | J36: S | K36: S | L36: S | M36: S | N36: US | O36: US | U36: =IF(A36="","", IF(COUNTIF(E36:T36,"US")>=3,0, 10-COUNTIF(E36:T36,"US"))) -> 8
A37: =IF(Data_input!A37="","",Data_input!A37) -> 245MK | B37: =IF(Data_input!B37="","",Data_input!B37) -> 250PR284PK | C37: =IF(Data_input!C37="","",Data_input!C37) -> ABDUL RAHMAN BIN OTHMAN | D37: =IF(Data_input!L37="","",Data_input!L37) -> Master (Law) | E37: S | F37: S | G37: S | H37: S | I37: S | J37: S | K37: S | L37: S | M37: S | N37: US | O37: S | U37: =IF(A37="","", IF(COUNTIF(E37:T37,"US")>=3,0, 10-COUNTIF(E37:T37,"US"))) -> 9
A38: =IF(Data_input!A38="","",Data_input!A38) -> 248RM | B38: =IF(Data_input!B38="","",Data_input!B38) -> 250PS295RM | C38: =IF(Data_input!C38="","",Data_input!C38) -> YAP SIEW LING | D38: =IF(Data_input!L38="","",Data_input!L38) -> Master (Communication) | E38: NA | F38: S | G38: S | H38: US | I38: US | J38: S | K38: US | L38: S | M38: S | N38: S | O38: S | U38: =IF(A38="","", IF(COUNTIF(E38:T38,"US")>=3,0, 10-COUNTIF(E38:T38,"US"))) -> 0
A39: =IF(Data_input!A39="","",Data_input!A39) -> 249RK | B39: =IF(Data_input!B39="","",Data_input!B39) -> 250PT244R3 | C39: =IF(Data_input!C39="","",Data_input!C39) -> MIRA SHARMINA BINTI HAMZAH | D39: =IF(Data_input!L39="","",Data_input!L39) -> Master (Communication) | E39: S | F39: S | G39: S | H39: S | I39: S | J39: US | K39: US | L39: US | M39: S | N39: S | O39: S | U39: =IF(A39="","", IF(COUNTIF(E39:T39,"US")>=3,0, 10-COUNTIF(E39:T39,"US"))) -> 0
A40: =IF(Data_input!A40="","",Data_input!A40) -> 247LH | B40: =IF(Data_input!B40="","",Data_input!B40) -> 250PS297RL | C40: =IF(Data_input!C40="","",Data_input!C40) -> KOH CHEE MING | D40: =IF(Data_input!L40="","",Data_input!L40) -> Master (Communication) | E40: S | F40: S | G40: S | H40: S | I40: S | J40: S | K40: US | L40: US | M40: US | N40: S | O40: S | U40: =IF(A40="","", IF(COUNTIF(E40:T40,"US")>=3,0, 10-COUNTIF(E40:T40,"US"))) -> 0
...

Sheet Data_count
A1: CAMPUS_ID | B1: Student_ID | C1: Name | D1: Submition_RPD_Day | E1: ThesisSem_Day | F1: PublicationRequirement_paper1_Day（PHD/Master） | G1: PublicationRequirement_paper2_Day（PHD）
A2: =IF(Data_input!A2="","",Data_input!A2) -> 247R1 | B2: =IF(Data_input!B2="","",Data_input!B2) -> 250PA247R8 | C2: =IF(Data_input!C2="","",Data_input!C2) -> USMAN YAU | D2: =IF(OR(data_coll!R2="", data_coll!G2=""), "", _xlfn.DAYS(data_coll!R2, data_coll!G2)) -> 163 | E2: =IF(OR(data_coll!T2="",data_coll!U2=""),"",data_coll!U2-data_coll!T2) -> 245 | F2: =IF(OR(data_coll!W2="", data_coll!G2=""), "", _xlfn.DAYS(data_coll!W2, data_coll!G2)) -> 4 | G2: =IF(OR(data_coll!X2="", data_coll!G2=""), "", _xlfn.DAYS(data_coll!X2, data_coll!G2)) -> 567
A3: =IF(Data_input!A3="","",Data_input!A3) -> 247R4 | B3: =IF(Data_input!B3="","",Data_input!B3) -> 250PA247R1 | C3: =IF(Data_input!C3="","",Data_input!C3) -> KHAN IRFAN | D3: =IF(OR(data_coll!R3="", data_coll!G3=""), "", _xlfn.DAYS(data_coll!R3, data_coll!G3)) -> 163 | E3: =IF(OR(data_coll!T3="",data_coll!U3=""),"",data_coll!U3-data_coll!T3) -> 256 | F3: =IF(OR(data_coll!W3="", data_coll!G3=""), "", _xlfn.DAYS(data_coll!W3, data_coll!G3)) -> 528 | G3: =IF(OR(data_coll!X3="", data_coll!G3=""), "", _xlfn.DAYS(data_coll!X3, data_coll!G3)) -> 537
A4: =IF(Data_input!A4="","",Data_input!A4) -> 247R8 | B4: =IF(Data_input!B4="","",Data_input!B4) -> 250PA247R2 | C4: =IF(Data_input!C4="","",Data_input!C4) -> JAYAKANTHAN A/L M. LACHMANAN | D4: =IF(OR(data_coll!R4="", data_coll!G4=""), "", _xlfn.DAYS(data_coll!R4, data_coll!G4)) -> 177 | E4: =IF(OR(data_coll!T4="",data_coll!U4=""),"",data_coll!U4-data_coll!T4) -> 222 | F4: =IF(OR(data_coll!W4="", data_coll!G4=""), "", _xlfn.DAYS(data_coll!W4, data_coll!G4)) -> 510 | G4: =IF(OR(data_coll!X4="", data_coll!G4=""), "", _xlfn.DAYS(data_coll!X4, data_coll!G4)) -> 519
A5: =IF(Data_input!A5="","",Data_input!A5) -> 247R3 | B5: =IF(Data_input!B5="","",Data_input!B5) -> 250PA247R5 | C5: =IF(Data_input!C5="","",Data_input!C5) -> IDRIS OLALEKAN ADEOYE | D5: =IF(OR(data_coll!R5="", data_coll!G5=""), "", _xlfn.DAYS(data_coll!R5, data_coll!G5)) -> 213 | E5: =IF(OR(data_coll!T5="",data_coll!U5=""),"",data_coll!U5-data_coll!T5) -> 144 | F5: =IF(OR(data_coll!W5="", data_coll!G5=""), "", _xlfn.DAYS(data_coll!W5, data_coll!G5)) -> 577 | G5: =IF(OR(data_coll!X5="", data_coll!G5=""), "", _xlfn.DAYS(data_coll!X5, data_coll!G5)) -> 586
A6: =IF(Data_input!A6="","",Data_input!A6) -> 247R7 | B6: =IF(Data_input!B6="","",Data_input!B6) -> 250PA247R7 | C6: =IF(Data_input!C6="","",Data_input!C6) -> NUHU DAN-AZUMI MUHAMMAD | D6: =IF(OR(data_coll!R6="", data_coll!G6=""), "", _xlfn.DAYS(data_coll!R6, data_coll!G6)) -> 213 | E6: =IF(OR(data_coll!T6="",data_coll!U6=""),"",data_coll!U6-data_coll!T6) -> 138 | F6: =IF(OR(data_coll!W6="", data_coll!G6=""), "", _xlfn.DAYS(data_coll!W6, data_coll!G6)) -> 578 | G6: =IF(OR(data_coll!X6="", data_coll!G6=""), "", _xlfn.DAYS(data_coll!X6, data_coll!G6)) -> 587
A7: =IF(Data_input!A7="","",Data_input!A7) -> 2508F | B7: =IF(Data_input!B7="","",Data_input!B7) -> 250PA257R3 | C7: =IF(Data_input!C7="","",Data_input!C7) -> NAZ ANUM | D7: =IF(OR(data_coll!R7="", data_coll!G7=""), "", _xlfn.DAYS(data_coll!R7, data_coll!G7)) -> 215 | E7: =IF(OR(data_coll!T7="",data_coll!U7=""),"",data_coll!U7-data_coll!T7) -> 142 | F7: =IF(OR(data_coll!W7="", data_coll!G7=""), "", _xlfn.DAYS(data_coll!W7, data_coll!G7)) -> 580 | G7: =IF(OR(data_coll!X7="", data_coll!G7=""), "", _xlfn.DAYS(data_coll!X7, data_coll!G7)) -> 589
A8: =IF(Data_input!A8="","",Data_input!A8) -> 243YN | B8: =IF(Data_input!B8="","",Data_input!B8) -> 250PA237R1 | C8: =IF(Data_input!C8="","",Data_input!C8) -> NUR SYAZA BINTI ZAKARIA | D8: =IF(OR(data_coll!R8="", data_coll!G8=""), "", _xlfn.DAYS(data_coll!R8, data_coll!G8)) -> 547 | E8: =IF(OR(data_coll!T8="",data_coll!U8=""),"",data_coll!U8-data_coll!T8) -> -12 | F8: =IF(OR(data_coll!W8="", data_coll!G8=""), "", _xlfn.DAYS(data_coll!W8, data_coll!G8)) -> 912 | G8: =IF(OR(data_coll!X8="", data_coll!G8=""), "", _xlfn.DAYS(data_coll!X8, data_coll!G8)) -> 912
A9: =IF(Data_input!A9="","",Data_input!A9) -> 251D4 | B9: =IF(Data_input!B9="","",Data_input!B9) -> 250PK242QD | C9: =IF(Data_input!C9="","",Data_input!C9) -> YANG XIAO | D9: =IF(OR(data_coll!R9="", data_coll!G9=""), "", _xlfn.DAYS(data_coll!R9, data_coll!G9)) -> 383 | E9: =IF(OR(data_coll!T9="",data_coll!U9=""),"",data_coll!U9-data_coll!T9) -> -13 | F9: =IF(OR(data_coll!W9="", data_coll!G9=""), "", _xlfn.DAYS(data_coll!W9, data_coll!G9)) -> 870 | G9: =IF(OR(data_coll!X9="", data_coll!G9=""), "", _xlfn.DAYS(data_coll!X9, data_coll!G9)) -> 872
A10: =IF(Data_input!A10="","",Data_input!A10) -> 2458H | B10: =IF(Data_input!B10="","",Data_input!B10) -> 250PK232QD | C10: =IF(Data_input!C10="","",Data_input!C10) -> MD MUSLIM UDDIN AHMED PIPUL | D10: =IF(OR(data_coll!R10="", data_coll!G10=""), "", _xlfn.DAYS(data_coll!R10, data_coll!G10)) -> 520 | E10: =IF(OR(data_coll!T10="",data_coll!U10=""),"",data_coll!U10-data_coll!T10) -> -14 | F10: =IF(OR(data_coll!W10="", data_coll!G10=""), "", _xlfn.DAYS(data_coll!W10, data_coll!G10)) -> 885 | G10: =IF(OR(data_coll!X10="", data_coll!G10=""), "", _xlfn.DAYS(data_coll!X10, data_coll!G10)) -> 885
A11: =IF(Data_input!A11="","",Data_input!A11) -> 252QD | B11: =IF(Data_input!B11="","",Data_input!B11) -> 250PK222QD | C11: =IF(Data_input!C11="","",Data_input!C11) -> JOANNA A/P JAYAPRAKASH | D11: =IF(OR(data_coll!R11="", data_coll!G11=""), "", _xlfn.DAYS(data_coll!R11, data_coll!G11)) -> 541 | E11: =IF(OR(data_coll!T11="",data_coll!U11=""),"",data_coll!U11-data_coll!T11) -> -15 | F11: =IF(OR(data_coll!W11="", data_coll!G11=""), "", _xlfn.DAYS(data_coll!W11, data_coll!G11)) -> 906 | G11: =IF(OR(data_coll!X11="", data_coll!G11=""), "", _xlfn.DAYS(data_coll!X11, data_coll!G11)) -> 906
A12: =IF(Data_input!A12="","",Data_input!A12) -> 243YN | B12: =IF(Data_input!B12="","",Data_input!B12) -> 250PK212QD | C12: =IF(Data_input!C12="","",Data_input!C12) -> HAMZA BASHER ALAMIN BARKA | D12: =IF(OR(data_coll!R12="", data_coll!G12=""), "", _xlfn.DAYS(data_coll!R12, data_coll!G12)) -> 133 | E12: =IF(OR(data_coll!T12="",data_coll!U12=""),"",data_coll!U12-data_coll!T12) -> 989 | F12: =IF(OR(data_coll!W12="", data_coll!G12=""), "", _xlfn.DAYS(data_coll!W12, data_coll!G12)) -> 97 | G12: =IF(OR(data_coll!X12="", data_coll!G12=""), "", _xlfn.DAYS(data_coll!X12, data_coll!G12)) -> 97
A13: =IF(Data_input!A13="","",Data_input!A13) -> 247R7 | B13: =IF(Data_input!B13="","",Data_input!B13) -> 250PK272QD | C13: =IF(Data_input!C13="","",Data_input!C13) -> NAHIDA FERDOUS | D13: =IF(OR(data_coll!R13="", data_coll!G13=""), "", _xlfn.DAYS(data_coll!R13, data_coll!G13)) -> 70 | E13: =IF(OR(data_coll!T13="",data_coll!U13=""),"",data_coll!U13-data_coll!T13) -> 988 | F13: =IF(OR(data_coll!W13="", data_coll!G13=""), "", _xlfn.DAYS(data_coll!W13, data_coll!G13)) -> 430 | G13: =IF(OR(data_coll!X13="", data_coll!G13=""), "", _xlfn.DAYS(data_coll!X13, data_coll!G13)) -> 440
... A60: =IF(Data_input!A60="","",Data_input!A60) | B60: =IF(Data_input!B60="","",Data_input!B60) | C60: =IF(Data_input!C60="","",Data_input!C60) | D60: =IF(OR(data_coll!R60="", data_coll!G60=""), "", _xlfn.DAYS(data_coll!R60, data_coll!G60)) | E60: =IF(OR(data_coll!T60="",data_coll!U60=""),"",data_coll!U60-data_coll!T60) | F60: =IF(OR(data_coll!W60="", data_coll!G60=""), "", _xlfn.DAYS(data_coll!W60, data_coll!G60)) | G60: =IF(OR(data_coll!X60="", data_coll!G60=""), "", _xlfn.DAYS(data_coll!X60, data_coll!G60))
A61: =IF(Data_input!A61="","",Data_input!A61)
A62: =IF(Data_input!A62="","",Data_input!A62)
A63: =IF(Data_input!A63="","",Data_input!A63)
A64: =IF(Data_input!A64="","",Data_input!A64)
A65: =IF(Data_input!A65="","",Data_input!A65)
A66: =IF(Data_input!A66="","",Data_input!A66)

Sheet Data_preview
A1: CAMPUS_ID | B1: Student_ID | C1: Name | D1: Prog_short_Des | E1: ProgressSpeed_RPD | F1: Progress_GredThesisSeminar | G1: PublicationRequirement_paper1_Day（PHD/Master） | H1: PublicationRequirement_paper2_Day（PHD） | I1: Overall_Evaluation
A2: =IF(Data_input!A2="","",Data_input!A2) -> 247R1 | B2: =IF(Data_input!B2="","",Data_input!B2) -> 250PA247R8 | C2: =IF(Data_input!C2="","",Data_input!C2) -> USMAN YAU | D2: =IF(Data_input!L2="","",Data_input!L2) -> Ph.D. (Eng) | E2: =IF(Data_count!D2="", "", IF(Data_count!D2<180, "Great", IF(Data_count!D2<270, "Normal", "Bad") ) ) -> Great | F2: =IF(Data_count!E2="","", IF(Data_count!E2>=200,"Great", IF(Data_count!E2>0,"Normal","Bad"))) -> Great | G2: =IF(Data_count!F2="","", IF(ISNUMBER(SEARCH("Ph.D",D2)), IF(Data_count!F2<=540,"Great", IF(Data_count!F2<=720,"Normal","Bad")), IF(Data_count!F2<=210,"Great", IF(Data_count!F2<=450,"Normal","Bad")) )) -> Great | H2: =IF(Data_count!G2="","", IF(ISNUMBER(SEARCH("Ph.D",D2)), IF(Data_count!G2<=540,"Great", IF(Data_count!G2<=720,"Normal","Bad")), IF(Data_count!G2<=210,"Great", IF(Data_count!G2<=450,"Normal","Bad")) )) -> Normal | I2: {=_xlfn.LET( _xlpm.r, E2:H2, _xlpm.t, UPPER(TRIM(_xlpm.r)), _xlpm.n, SUMPRODUCT(--((_xlpm.t="GREAT")+(_xlpm.t="NORMAL")+(_xlpm.t="BAD")>0)), _xlpm.thr, ROUNDUP(_xlpm.n*2/3,0), _xlpm.badc, SUMPRODUCT(--(_xlpm.t="BAD")), _xlpm.grc, SUMPRODUCT(--(_xlpm.t="GREAT")), IF(_xlpm.n=0,"", IF(_xlpm.badc>=_xlpm.thr,"Bad", IF(_xlpm.grc>=_xlpm.thr,"Good","Average"))) )} -> Good
A3: =IF(Data_input!A3="","",Data_input!A3) -> 247R4 | B3: =IF(Data_input!B3="","",Data_input!B3) -> 250PA247R1 | C3: =IF(Data_input!C3="","",Data_input!C3) -> KHAN IRFAN | D3: =IF(Data_input!L3="","",Data_input!L3) -> Ph.D. (Eng) | E3: =IF(Data_count!D3="", "", IF(Data_count!D3<180, "Great", IF(Data_count!D3<270, "Normal", "Bad") ) ) -> Great | F3: =IF(Data_count!E3="","", IF(Data_count!E3>=200,"Great", IF(Data_count!E3>0,"Normal","Bad"))) -> Great | G3: =IF(Data_count!F3="","", IF(ISNUMBER(SEARCH("Ph.D",D3)), IF(Data_count!F3<=540,"Great", IF(Data_count!F3<=720,"Normal","Bad")), IF(Data_count!F3<=210,"Great", IF(Data_count!F3<=450,"Normal","Bad")) )) -> Great | H3: =IF(Data_count!G3="","", IF(ISNUMBER(SEARCH("Ph.D",D3)), IF(Data_count!G3<=540,"Great", IF(Data_count!G3<=720,"Normal","Bad")), IF(Data_count!G3<=210,"Great", IF(Data_count!G3<=450,"Normal","Bad")) )) -> Great | I3: {=_xlfn.LET( _xlpm.r, E3:H3, _xlpm.t, UPPER(TRIM(_xlpm.r)), _xlpm.n, SUMPRODUCT(--((_xlpm.t="GREAT")+(_xlpm.t="NORMAL")+(_xlpm.t="BAD")>0)), _xlpm.thr, ROUNDUP(_xlpm.n*2/3,0), _xlpm.badc, SUMPRODUCT(--(_xlpm.t="BAD")), _xlpm.grc, SUMPRODUCT(--(_xlpm.t="GREAT")), IF(_xlpm.n=0,"", IF(_xlpm.badc>=_xlpm.thr,"Bad", IF(_xlpm.grc>=_xlpm.thr,"Good","Average"))) )} -> Good
